2024-03-06 10:23:48,406 - instabot version: 0.117.0 (bot) - INFO - Instabot version: 0.117.0 Started
2024-03-06 10:23:48,406 - instabot version: 0.117.0 (bot) - DEBUG - Bot imported from C:\Users\Admin\AppData\Local\Programs\Python\Python312\Lib\site-packages\instabot\bot\bot.py
2024-03-06 10:24:18,407 - instabot version: 0.117.0 (api_login) - INFO - Not yet logged in starting: PRE-LOGIN FLOW!
2024-03-06 10:24:29,631 - instabot version: 0.117.0 (api) - WARNING - HTTPSConnectionPool(host='i.instagram.com', port=443): Max retries exceeded with url: /api/v1/accounts/get_prefill_candidates/ (Caused by NameResolutionError("<urllib3.connection.HTTPSConnection object at 0x0000028C6FC523C0>: Failed to resolve 'i.instagram.com' ([Errno 11001] getaddrinfo failed)"))
2024-03-06 10:24:40,876 - instabot version: 0.117.0 (api) - WARNING - HTTPSConnectionPool(host='i.instagram.com', port=443): Max retries exceeded with url: /api/v1/qe/sync/ (Caused by NameResolutionError("<urllib3.connection.HTTPSConnection object at 0x0000028C6FC52E10>: Failed to resolve 'i.instagram.com' ([Errno 11001] getaddrinfo failed)"))
2024-03-06 10:24:40,892 - instabot version: 0.117.0 (api) - WARNING - HTTPSConnectionPool(host='i.instagram.com', port=443): Max retries exceeded with url: /api/v1/launcher/sync/ (Caused by NameResolutionError("<urllib3.connection.HTTPSConnection object at 0x0000028C6FC52EA0>: Failed to resolve 'i.instagram.com' ([Errno 11001] getaddrinfo failed)"))
2024-03-06 10:24:40,897 - instabot version: 0.117.0 (api) - WARNING - HTTPSConnectionPool(host='i.instagram.com', port=443): Max retries exceeded with url: /api/v1/accounts/contact_point_prefill/ (Caused by NameResolutionError("<urllib3.connection.HTTPSConnection object at 0x0000028C6FC53260>: Failed to resolve 'i.instagram.com' ([Errno 11001] getaddrinfo failed)"))
